TASK [pgadmin4 : Set permissions on /home/cloud-user/rpms] *********************
changed: [182.2.26.251]

TASK [pgadmin4 : Install local rpms] *******************************************
changed: [182.2.26.251] => (item=httpd)
An exception occurred during task execution. To see the full traceback, use -vvv. The error was: OSError: Could not open: /home/cloud-user/postgresql15-libs-15.1-1PGDG.rhel9.x86_64.rpm
failed: [182.2.26.251] (item=/home/cloud-user/postgresql15-libs-15.1-1PGDG.rhel9.x86_64.rpm) => {"ansible_loop_var": "item", "changed": false, "item": "/home/cloud-user/postgresql15-libs-15.1-1PGDG.rhel9.x86_64.rpm", "module_stderr": "Shared connection to 182.2.26.251 closed.\r\n", "module_stdout": "Traceback (most recent call last):\r\n  File \"/home/cloud-user/.ansible/tmp/ansible-tmp-1734378572.5466435-224-85861668034965/AnsiballZ_dnf.py\", line 100, in <module>\r\n    _ansiballz_main()\r\n  File \"/home/cloud-user/.ansible/tmp/ansible-tmp-1734378572.5466435-224-85861668034965/AnsiballZ_dnf.py\", line 92, in _ansiballz_main\r\n    invoke_module(zipped_mod, temp_path, ANSIBALLZ_PARAMS)\r\n  File \"/home/cloud-user/.ansible/tmp/ansible-tmp-1734378572.5466435-224-85861668034965/AnsiballZ_dnf.py\", line 40, in invoke_module\r\n    runpy.run_module(mod_name='ansible.modules.dnf', init_globals=dict(_module_fqn='ansible.modules.dnf', _modlib_path=modlib_path),\r\n  File \"/usr/lib64/python3.9/runpy.py\", line 225, in run_module\r\n    return _run_module_code(code, init_globals, run_name, mod_spec)\r\n  File \"/usr/lib64/python3.9/runpy.py\", line 97, in _run_module_code\r\n    _run_code(code, mod_globals, init_globals,\r\n  File \"/usr/lib64/python3.9/runpy.py\", line 87, in _run_code\r\n    exec(code, run_globals)\r\n  File \"/tmp/ansible_dnf_payload_lsyzh8d1/ansible_dnf_payload.zip/ansible/modules/dnf.py\", line 1363, in <module>\r\n  File \"/tmp/ansible_dnf_payload_lsyzh8d1/ansible_dnf_payload.zip/ansible/modules/dnf.py\", line 1352, in main\r\n  File \"/tmp/ansible_dnf_payload_lsyzh8d1/ansible_dnf_payload.zip/ansible/modules/dnf.py\", line 1326, in run\r\n  File \"/tmp/ansible_dnf_payload_lsyzh8d1/ansible_dnf_payload.zip/ansible/modules/dnf.py\", line 984, in ensure\r\n  File \"/tmp/ansible_dnf_payload_lsyzh8d1/ansible_dnf_payload.zip/ansible/modules/dnf.py\", line 884, in _install_remote_rpms\r\n  File \"/usr/lib/python3.9/site-packages/dnf/base.py\", line 1343, in add_remote_rpms\r\n    raise IOError(_(\"Could not open: {}\").format(' '.join(pkgs_error)))\r\nOSError: Could not open: /home/cloud-user/postgresql15-libs-15.1-1PGDG.rhel9.x86_64.rpm\r\n", "msg": "MODULE FAILURE\nSee stdout/stderr for the exact error", "rc": 1}
An exception occurred during task execution. To see the full traceback, use -vvv. The error was: OSError: Could not open: /home/cloud-user/postgresql15-15.1-1PGDG.rhel9.x86_64.rpm
failed: [182.2.26.251] (item=/home/cloud-user/postgresql15-15.1-1PGDG.rhel9.x86_64.rpm) => {"ansible_loop_var": "item", "changed": false, "item": "/home/cloud-user/postgresql15-15.1-1PGDG.rhel9.x86_64.rpm", "module_stderr": "Shared connection to 182.2.26.251 closed.\r\n", "module_stdout": "Traceback (most recent call last):\r\n  File \"/home/cloud-user/.ansible/tmp/ansible-tmp-1734378573.8156016-224-11916270467995/AnsiballZ_dnf.py\", line 100, in <module>\r\n    _ansiballz_main()\r\n  File \"/home/cloud-user/.ansible/tmp/ansible-tmp-1734378573.8156016-224-11916270467995/AnsiballZ_dnf.py\", line 92, in _ansiballz_main\r\n    invoke_module(zipped_mod, temp_path, ANSIBALLZ_PARAMS)\r\n  File \"/home/cloud-user/.ansible/tmp/ansible-tmp-1734378573.8156016-224-11916270467995/AnsiballZ_dnf.py\", line 40, in invoke_module\r\n    runpy.run_module(mod_name='ansible.modules.dnf', init_globals=dict(_module_fqn='ansible.modules.dnf', _modlib_path=modlib_path),\r\n  File \"/usr/lib64/python3.9/runpy.py\", line 225, in run_module\r\n    return _run_module_code(code, init_globals, run_name, mod_spec)\r\n  File \"/usr/lib64/python3.9/runpy.py\", line 97, in _run_module_code\r\n    _run_code(code, mod_globals, init_globals,\r\n  File \"/usr/lib64/python3.9/runpy.py\", line 87, in _run_code\r\n    exec(code, run_globals)\r\n  File \"/tmp/ansible_dnf_payload_a8p_gk5f/ansible_dnf_payload.zip/ansible/modules/dnf.py\", line 1363, in <module>\r\n  File \"/tmp/ansible_dnf_payload_a8p_gk5f/ansible_dnf_payload.zip/ansible/modules/dnf.py\", line 1352, in main\r\n  File \"/tmp/ansible_dnf_payload_a8p_gk5f/ansible_dnf_payload.zip/ansible/modules/dnf.py\", line 1326, in run\r\n  File \"/tmp/ansible_dnf_payload_a8p_gk5f/ansible_dnf_payload.zip/ansible/modules/dnf.py\", line 984, in ensure\r\n  File \"/tmp/ansible_dnf_payload_a8p_gk5f/ansible_dnf_payload.zip/ansible/modules/dnf.py\", line 884, in _install_remote_rpms\r\n  File \"/usr/lib/python3.9/site-packages/dnf/base.py\", line 1343, in add_remote_rpms\r\n    raise IOError(_(\"Could not open: {}\").format(' '.join(pkgs_error)))\r\nOSError: Could not open: /home/cloud-user/postgresql15-15.1-1PGDG.rhel9.x86_64.rpm\r\n", "msg": "MODULE FAILURE\nSee stdout/stderr for the exact error", "rc": 1}
An exception occurred during task execution. To see the full traceback, use -vvv. The error was: OSError: Could not open: /home/cloud-user/postgresql15-server-15.1-1PGDG.rhel9.x86_64.rpm
failed: [182.2.26.251] (item=/home/cloud-user/postgresql15-server-15.1-1PGDG.rhel9.x86_64.rpm) => {"ansible_loop_var": "item", "changed": false, "item": "/home/cloud-user/postgresql15-server-15.1-1PGDG.rhel9.x86_64.rpm", "module_stderr": "Shared connection to 182.2.26.251 closed.\r\n", "module_stdout": "Traceback (most recent call last):\r\n  File \"/home/cloud-user/.ansible/tmp/ansible-tmp-1734378575.0947037-224-276173545942291/AnsiballZ_dnf.py\", line 100, in <module>\r\n    _ansiballz_main()\r\n  File \"/home/cloud-user/.ansible/tmp/ansible-tmp-1734378575.0947037-224-276173545942291/AnsiballZ_dnf.py\", line 92, in _ansiballz_main\r\n    invoke_module(zipped_mod, temp_path, ANSIBALLZ_PARAMS)\r\n  File \"/home/cloud-user/.ansible/tmp/ansible-tmp-1734378575.0947037-224-276173545942291/AnsiballZ_dnf.py\", line 40, in invoke_module\r\n    runpy.run_module(mod_name='ansible.modules.dnf', init_globals=dict(_module_fqn='ansible.modules.dnf', _modlib_path=modlib_path),\r\n  File \"/usr/lib64/python3.9/runpy.py\", line 225, in run_module\r\n    return _run_module_code(code, init_globals, run_name, mod_spec)\r\n  File \"/usr/lib64/python3.9/runpy.py\", line 97, in _run_module_code\r\n    _run_code(code, mod_globals, init_globals,\r\n  File \"/usr/lib64/python3.9/runpy.py\", line 87, in _run_code\r\n    exec(code, run_globals)\r\n  File \"/tmp/ansible_dnf_payload_r3soxno0/ansible_dnf_payload.zip/ansible/modules/dnf.py\", line 1363, in <module>\r\n  File \"/tmp/ansible_dnf_payload_r3soxno0/ansible_dnf_payload.zip/ansible/modules/dnf.py\", line 1352, in main\r\n  File \"/tmp/ansible_dnf_payload_r3soxno0/ansible_dnf_payload.zip/ansible/modules/dnf.py\", line 1326, in run\r\n  File \"/tmp/ansible_dnf_payload_r3soxno0/ansible_dnf_payload.zip/ansible/modules/dnf.py\", line 984, in ensure\r\n  File \"/tmp/ansible_dnf_payload_r3soxno0/ansible_dnf_payload.zip/ansible/modules/dnf.py\", line 884, in _install_remote_rpms\r\n  File \"/usr/lib/python3.9/site-packages/dnf/base.py\", line 1343, in add_remote_rpms\r\n    raise IOError(_(\"Could not open: {}\").format(' '.join(pkgs_error)))\r\nOSError: Could not open: /home/cloud-user/postgresql15-server-15.1-1PGDG.rhel9.x86_64.rpm\r\n", "msg": "MODULE FAILURE\nSee stdout/stderr for the exact error", "rc": 1}
An exception occurred during task execution. To see the full traceback, use -vvv. The error was: OSError: Could not open: /home/cloud-user/postgresql15-contrib-15.1-1PGDG.rhel9.x86_64.rpm
failed: [182.2.26.251] (item=/home/cloud-user/postgresql15-contrib-15.1-1PGDG.rhel9.x86_64.rpm) => {"ansible_loop_var": "item", "changed": false, "item": "/home/cloud-user/postgresql15-contrib-15.1-1PGDG.rhel9.x86_64.rpm", "module_stderr": "Shared connection to 182.2.26.251 closed.\r\n", "module_stdout": "Traceback (most recent call last):\r\n  File \"/home/cloud-user/.ansible/tmp/ansible-tmp-1734378576.3826966-224-174690111020045/AnsiballZ_dnf.py\", line 100, in <module>\r\n    _ansiballz_main()\r\n  File \"/home/cloud-user/.ansible/tmp/ansible-tmp-1734378576.3826966-224-174690111020045/AnsiballZ_dnf.py\", line 92, in _ansiballz_main\r\n    invoke_module(zipped_mod, temp_path, ANSIBALLZ_PARAMS)\r\n  File \"/home/cloud-user/.ansible/tmp/ansible-tmp-1734378576.3826966-224-174690111020045/AnsiballZ_dnf.py\", line 40, in invoke_module\r\n    runpy.run_module(mod_name='ansible.modules.dnf', init_globals=dict(_module_fqn='ansible.modules.dnf', _modlib_path=modlib_path),\r\n  File \"/usr/lib64/python3.9/runpy.py\", line 225, in run_module\r\n    return _run_module_code(code, init_globals, run_name, mod_spec)\r\n  File \"/usr/lib64/python3.9/runpy.py\", line 97, in _run_module_code\r\n    _run_code(code, mod_globals, init_globals,\r\n  File \"/usr/lib64/python3.9/runpy.py\", line 87, in _run_code\r\n    exec(code, run_globals)\r\n  File \"/tmp/ansible_dnf_payload_l42s1c5t/ansible_dnf_payload.zip/ansible/modules/dnf.py\", line 1363, in <module>\r\n  File \"/tmp/ansible_dnf_payload_l42s1c5t/ansible_dnf_payload.zip/ansible/modules/dnf.py\", line 1352, in main\r\n  File \"/tmp/ansible_dnf_payload_l42s1c5t/ansible_dnf_payload.zip/ansible/modules/dnf.py\", line 1326, in run\r\n  File \"/tmp/ansible_dnf_payload_l42s1c5t/ansible_dnf_payload.zip/ansible/modules/dnf.py\", line 984, in ensure\r\n  File \"/tmp/ansible_dnf_payload_l42s1c5t/ansible_dnf_payload.zip/ansible/modules/dnf.py\", line 884, in _install_remote_rpms\r\n  File \"/usr/lib/python3.9/site-packages/dnf/base.py\", line 1343, in add_remote_rpms\r\n    raise IOError(_(\"Could not open: {}\").format(' '.join(pkgs_error)))\r\nOSError: Could not open: /home/cloud-user/postgresql15-contrib-15.1-1PGDG.rhel9.x86_64.rpm\r\n", "msg": "MODULE FAILURE\nSee stdout/stderr for the exact error", "rc": 1}
An exception occurred during task execution. To see the full traceback, use -vvv. The error was: OSError: Could not open: /home/cloud-user/pgadmin4-server-8.9-1.el9.x86_64.rpm
failed: [182.2.26.251] (item=/home/cloud-user/pgadmin4-server-8.9-1.el9.x86_64.rpm) => {"ansible_loop_var": "item", "changed": false, "item": "/home/cloud-user/pgadmin4-server-8.9-1.el9.x86_64.rpm", "module_stderr": "Shared connection to 182.2.26.251 closed.\r\n", "module_stdout": "Traceback (most recent call last):\r\n  File \"/home/cloud-user/.ansible/tmp/ansible-tmp-1734378577.7794182-224-145460459647430/AnsiballZ_dnf.py\", line 100, in <module>\r\n    _ansiballz_main()\r\n  File \"/home/cloud-user/.ansible/tmp/ansible-tmp-1734378577.7794182-224-145460459647430/AnsiballZ_dnf.py\", line 92, in _ansiballz_main\r\n    invoke_module(zipped_mod, temp_path, ANSIBALLZ_PARAMS)\r\n  File \"/home/cloud-user/.ansible/tmp/ansible-tmp-1734378577.7794182-224-145460459647430/AnsiballZ_dnf.py\", line 40, in invoke_module\r\n    runpy.run_module(mod_name='ansible.modules.dnf', init_globals=dict(_module_fqn='ansible.modules.dnf', _modlib_path=modlib_path),\r\n  File \"/usr/lib64/python3.9/runpy.py\", line 225, in run_module\r\n    return _run_module_code(code, init_globals, run_name, mod_spec)\r\n  File \"/usr/lib64/python3.9/runpy.py\", line 97, in _run_module_code\r\n    _run_code(code, mod_globals, init_globals,\r\n  File \"/usr/lib64/python3.9/runpy.py\", line 87, in _run_code\r\n    exec(code, run_globals)\r\n  File \"/tmp/ansible_dnf_payload_8wcxeg9v/ansible_dnf_payload.zip/ansible/modules/dnf.py\", line 1363, in <module>\r\n  File \"/tmp/ansible_dnf_payload_8wcxeg9v/ansible_dnf_payload.zip/ansible/modules/dnf.py\", line 1352, in main\r\n  File \"/tmp/ansible_dnf_payload_8wcxeg9v/ansible_dnf_payload.zip/ansible/modules/dnf.py\", line 1326, in run\r\n  File \"/tmp/ansible_dnf_payload_8wcxeg9v/ansible_dnf_payload.zip/ansible/modules/dnf.py\", line 984, in ensure\r\n  File \"/tmp/ansible_dnf_payload_8wcxeg9v/ansible_dnf_payload.zip/ansible/modules/dnf.py\", line 884, in _install_remote_rpms\r\n  File \"/usr/lib/python3.9/site-packages/dnf/base.py\", line 1343, in add_remote_rpms\r\n    raise IOError(_(\"Could not open: {}\").format(' '.join(pkgs_error)))\r\nOSError: Could not open: /home/cloud-user/pgadmin4-server-8.9-1.el9.x86_64.rpm\r\n", "msg": "MODULE FAILURE\nSee stdout/stderr for the exact error", "rc": 1}
An exception occurred during task execution. To see the full traceback, use -vvv. The error was: OSError: Could not open: /home/cloud-user/pgadmin4-web-8.9-1.el9.noarch.rpm
failed: [182.2.26.251] (item=/home/cloud-user/pgadmin4-web-8.9-1.el9.noarch.rpm) => {"ansible_loop_var": "item", "changed": false, "item": "/home/cloud-user/pgadmin4-web-8.9-1.el9.noarch.rpm", "module_stderr": "Shared connection to 182.2.26.251 closed.\r\n", "module_stdout": "Traceback (most recent call last):\r\n  File \"/home/cloud-user/.ansible/tmp/ansible-tmp-1734378579.2312334-224-71874659916592/AnsiballZ_dnf.py\", line 100, in <module>\r\n    _ansiballz_main()\r\n  File \"/home/cloud-user/.ansible/tmp/ansible-tmp-1734378579.2312334-224-71874659916592/AnsiballZ_dnf.py\", line 92, in _ansiballz_main\r\n    invoke_module(zipped_mod, temp_path, ANSIBALLZ_PARAMS)\r\n  File \"/home/cloud-user/.ansible/tmp/ansible-tmp-1734378579.2312334-224-71874659916592/AnsiballZ_dnf.py\", line 40, in invoke_module\r\n    runpy.run_module(mod_name='ansible.modules.dnf', init_globals=dict(_module_fqn='ansible.modules.dnf', _modlib_path=modlib_path),\r\n  File \"/usr/lib64/python3.9/runpy.py\", line 225, in run_module\r\n    return _run_module_code(code, init_globals, run_name, mod_spec)\r\n  File \"/usr/lib64/python3.9/runpy.py\", line 97, in _run_module_code\r\n    _run_code(code, mod_globals, init_globals,\r\n  File \"/usr/lib64/python3.9/runpy.py\", line 87, in _run_code\r\n    exec(code, run_globals)\r\n  File \"/tmp/ansible_dnf_payload_55_7fy03/ansible_dnf_payload.zip/ansible/modules/dnf.py\", line 1363, in <module>\r\n  File \"/tmp/ansible_dnf_payload_55_7fy03/ansible_dnf_payload.zip/ansible/modules/dnf.py\", line 1352, in main\r\n  File \"/tmp/ansible_dnf_payload_55_7fy03/ansible_dnf_payload.zip/ansible/modules/dnf.py\", line 1326, in run\r\n  File \"/tmp/ansible_dnf_payload_55_7fy03/ansible_dnf_payload.zip/ansible/modules/dnf.py\", line 984, in ensure\r\n  File \"/tmp/ansible_dnf_payload_55_7fy03/ansible_dnf_payload.zip/ansible/modules/dnf.py\", line 884, in _install_remote_rpms\r\n  File \"/usr/lib/python3.9/site-packages/dnf/base.py\", line 1343, in add_remote_rpms\r\n    raise IOError(_(\"Could not open: {}\").format(' '.join(pkgs_error)))\r\nOSError: Could not open: /home/cloud-user/pgadmin4-web-8.9-1.el9.noarch.rpm\r\n", "msg": "MODULE FAILURE\nSee stdout/stderr for the exact error", "rc": 1}
...ignoring

TASK [pgadmin4 : Delete RPMs directory after install] **************************
changed: [182.2.26.251]

TASK [pgadmin4 : Unmount volume if mounted "{{ volume_name }}"] ****************
skipping: [182.2.26.251]

TASK [pgadmin4 : Mount "{{ volume_name }}" in "{{ pgadmin_install_path|default('/pgadmin') }}"] ***
skipping: [182.2.26.251]

TASK [pgadmin4 : Make pgAdmin data directory] **********************************
changed: [182.2.26.251]

TASK [pgadmin4 : Ensure local config directory exists] *************************
changed: [182.2.26.251]

TASK [pgadmin4 : Create local config file] *************************************
changed: [182.2.26.251]

TASK [pgadmin4 : Switch setup-web.sh to AUTOMATED=1] ***************************
fatal: [182.2.26.251]: FAILED! => {"changed": false, "msg": "Destination /usr/pgadmin4/bin/setup-web.sh does not exist !", "rc": 257}

PLAY RECAP *********************************************************************
182.2.26.251               : ok=11   changed=10   unreachable=0    failed=1    skipped=2    rescued=0    ignored=1   

[Pipeline] }
[Pipeline] // container
[Pipeline] }
[Pipeline] // dir
[Pipeline] }
[Pipeline] // stage
[Pipeline] }
[Pipeline] // withVault
[Pipeline] }
[Pipeline] // withEnv
[Pipeline] }
[Pipeline] // node
[Pipeline] }
[Pipeline] // podTemplate
[Pipeline] End of Pipeline
ERROR: script returned exit code 2
Finished: FAILURE
