+ python /home/jenkins/agent/workspace/DJD/CD-Deploy/openr-pipeline-int/pipeline/lib/scripts/server_image_lookup.py backend
Traceback (most recent call last):
  File "/home/jenkins/.local/lib/python3.10/site-packages/urllib3/connection.py", line 174, in _new_conn
    conn = connection.create_connection(
  File "/home/jenkins/.local/lib/python3.10/site-packages/urllib3/util/connection.py", line 72, in create_connection
    for res in socket.getaddrinfo(host, port, family, socket.SOCK_STREAM):
  File "/usr/local/lib/python3.10/socket.py", line 955, in getaddrinfo
    for res in _socket.getaddrinfo(host, port, family, type, proto, flags):
socket.gaierror: [Errno -2] Name or service not known

During handling of the above exception, another exception occurred:

Traceback (most recent call last):
  File "/home/jenkins/.local/lib/python3.10/site-packages/urllib3/connectionpool.py", line 714, in urlopen
    httplib_response = self._make_request(
  File "/home/jenkins/.local/lib/python3.10/site-packages/urllib3/connectionpool.py", line 403, in _make_request
    self._validate_conn(conn)
  File "/home/jenkins/.local/lib/python3.10/site-packages/urllib3/connectionpool.py", line 1053, in _validate_conn
    conn.connect()
  File "/home/jenkins/.local/lib/python3.10/site-packages/urllib3/connection.py", line 363, in connect
    self.sock = conn = self._new_conn()
  File "/home/jenkins/.local/lib/python3.10/site-packages/urllib3/connection.py", line 186, in _new_conn
    raise NewConnectionError(
urllib3.exceptions.NewConnectionError: <urllib3.connection.HTTPSConnection object at 0x7f4155baa0b0>: Failed to establish a new connection: [Errno -2] Name or service not known

During handling of the above exception, another exception occurred:

Traceback (most recent call last):
  File "/home/jenkins/.local/lib/python3.10/site-packages/requests/adapters.py", line 486, in send
    resp = conn.urlopen(
  File "/home/jenkins/.local/lib/python3.10/site-packages/urllib3/connectionpool.py", line 798, in urlopen
    retries = retries.increment(
  File "/home/jenkins/.local/lib/python3.10/site-packages/urllib3/util/retry.py", line 592, in increment
    raise MaxRetryError(_pool, url, error or ResponseError(cause))
urllib3.exceptions.MaxRetryError: HTTPSConnectionPool(host='osfapi.eu-fr-', port=443): Max retries exceeded with url: / (Caused by NewConnectionError('<urllib3.connection.HTTPSConnection object at 0x7f4155baa0b0>: Failed to establish a new connection: [Errno -2] Name or service not known'))

During handling of the above exception, another exception occurred:

Traceback (most recent call last):
  File "/home/jenkins/agent/workspace/DJD/CD-Deploy/openr-pipeline-int/pipeline/lib/scripts/server_image_lookup.py", line 22, in <module>
    main()
  File "/home/jenkins/agent/workspace/DJD/CD-Deploy/openr-pipeline-int/pipeline/lib/scripts/server_image_lookup.py", line 19, in main
    get_ocs_image_id(server_name)
  File "/home/jenkins/agent/workspace/DJD/CD-Deploy/openr-pipeline-int/pipeline/lib/scripts/server_image_lookup.py", line 12, in get_ocs_image_id
    image_name = sg_cloud_client.get_image_details(image_id)
  File "/home/jenkins/agent/workspace/DJD/CD-Deploy/openr-pipeline-int/pipeline/lib/common/sgcloud.py", line 398, in get_image_details
    res = http_client.get(
  File "/home/jenkins/agent/workspace/DJD/CD-Deploy/openr-pipeline-int/pipeline/lib/common/http_client.py", line 53, in get
    res = requests.get(
  File "/home/jenkins/.local/lib/python3.10/site-packages/requests/api.py", line 73, in get
    return request("get", url, params=params, **kwargs)
  File "/home/jenkins/.local/lib/python3.10/site-packages/requests/api.py", line 59, in request
    return session.request(method=method, url=url, **kwargs)
  File "/home/jenkins/.local/lib/python3.10/site-packages/requests/sessions.py", line 589, in request
    resp = self.send(prep, **send_kwargs)
  File "/home/jenkins/.local/lib/python3.10/site-packages/requests/sessions.py", line 703, in send
    r = adapter.send(request, **kwargs)
  File "/home/jenkins/.local/lib/python3.10/site-packages/requests/adapters.py", line 519, in send
    raise ConnectionError(e, request=request)
requests.exceptions.ConnectionError: HTTPSConnectionPool(host='osfapi.eu-fr-', port=443): Max retries exceeded with url: / (Caused by NewConnectionError('<urllib3.connection.HTTPSConnection object at 0x7f4155baa0b0>: Failed to establish a new connection: [Errno -2] Name or service not known'))
[Pipeline] }
